2024-09-29 17:47:11,776 | INFO | START BOT
2024-09-29 17:47:12,037 | INFO | Bot: IMGAi [@imagesAI_bot]
2024-09-29 17:47:12,037 | INFO | Start polling.
2024-09-29 17:47:17,074 | ERROR | Task exception was never retrieved
future: <Task finished name='Task-7' coro=<Dispatcher._process_polling_updates() done, defined at D:\Рабочий стол\Urban University\DIPLOM_project\.venv\lib\site-packages\aiogram\dispatcher\dispatcher.py:410> exception=FileNotFoundError(2, 'No such file or directory')>
Traceback (most recent call last):
  File "D:\Рабочий стол\Urban University\DIPLOM_project\.venv\lib\site-packages\aiogram\dispatcher\dispatcher.py", line 418, in _process_polling_updates
    for responses in itertools.chain.from_iterable(await self.process_updates(updates, fast)):
  File "D:\Рабочий стол\Urban University\DIPLOM_project\.venv\lib\site-packages\aiogram\dispatcher\dispatcher.py", line 236, in process_updates
    return await asyncio.gather(*tasks)
  File "D:\Рабочий стол\Urban University\DIPLOM_project\.venv\lib\site-packages\aiogram\dispatcher\handler.py", line 117, in notify
    response = await handler_obj.handler(*args, **partial_data)
  File "D:\Рабочий стол\Urban University\DIPLOM_project\.venv\lib\site-packages\aiogram\dispatcher\dispatcher.py", line 257, in process_update
    return await self.message_handlers.notify(update.message)
  File "D:\Рабочий стол\Urban University\DIPLOM_project\.venv\lib\site-packages\aiogram\dispatcher\handler.py", line 117, in notify
    response = await handler_obj.handler(*args, **partial_data)
  File "D:\Рабочий стол\Urban University\DIPLOM_project\IMGi_bot\function\setting_func.py", line 16, in set_style
    with open('./image_for_settings/style.png', mode='rb') as file:
FileNotFoundError: [Errno 2] No such file or directory: './image_for_settings/style.png'
2024-09-29 17:50:20,937 | INFO | Stop polling...
2024-09-29 17:50:20,937 | WARNING | Goodbye!
